2023-12-19 10:07:33,178 INFO    MainThread:14335 [wandb_setup.py:_flush():76] Configure stats pid to 14335
2023-12-19 10:07:33,180 INFO    MainThread:14335 [wandb_setup.py:_flush():76] Loading settings from /zhome/19/0/64415/.config/wandb/settings
2023-12-19 10:07:33,180 INFO    MainThread:14335 [wandb_setup.py:_flush():76] Loading settings from /work3/soeba/HALOS/wandb/settings
2023-12-19 10:07:33,181 INFO    MainThread:14335 [wandb_setup.py:_flush():76] Loading settings from environment variables: {'_require_service': 'True'}
2023-12-19 10:07:33,181 INFO    MainThread:14335 [wandb_setup.py:_flush():76] Inferring run settings from compute environment: {'program_relpath': 'esrgan_bones_v3-5.py', 'program': 'esrgan_bones_v3-5.py'}
2023-12-19 10:07:33,182 INFO    MainThread:14335 [wandb_init.py:_log_setup():461] Logging user logs to /work3/soeba/HALOS/wandb/run-20231219_100733-1r8nd9xw/logs/debug.log
2023-12-19 10:07:33,182 INFO    MainThread:14335 [wandb_init.py:_log_setup():462] Logging internal logs to /work3/soeba/HALOS/wandb/run-20231219_100733-1r8nd9xw/logs/debug-internal.log
2023-12-19 10:07:33,183 INFO    MainThread:14335 [wandb_init.py:init():495] calling init triggers
2023-12-19 10:07:33,183 INFO    MainThread:14335 [wandb_init.py:init():498] wandb.init called with sweep_config: {}
config: {}
2023-12-19 10:07:33,184 INFO    MainThread:14335 [wandb_init.py:init():548] starting backend
2023-12-19 10:07:33,184 INFO    MainThread:14335 [wandb_init.py:init():552] setting up manager
2023-12-19 10:07:33,199 INFO    MainThread:14335 [backend.py:_multiprocessing_setup():97] multiprocessing start_methods=fork,spawn,forkserver, using: spawn
2023-12-19 10:07:33,210 INFO    MainThread:14335 [wandb_init.py:init():558] backend started and connected
2023-12-19 10:07:33,217 INFO    MainThread:14335 [wandb_init.py:init():636] updated telemetry
2023-12-19 10:07:33,220 INFO    MainThread:14335 [wandb_init.py:init():667] communicating run to backend with 30 second timeout
2023-12-19 10:08:01,512 ERROR   Thread-1  :14335 [retry.py:__call__():154] Retry attempt failed:
Traceback (most recent call last):
  File "/work3/soeba/HALOS/halos/lib/python3.8/site-packages/urllib3/connectionpool.py", line 449, in _make_request
    six.raise_from(e, None)
  File "<string>", line 3, in raise_from
  File "/work3/soeba/HALOS/halos/lib/python3.8/site-packages/urllib3/connectionpool.py", line 444, in _make_request
    httplib_response = conn.getresponse()
  File "/appl/python/3.8.9/lib/python3.8/http/client.py", line 1344, in getresponse
    response.begin()
  File "/appl/python/3.8.9/lib/python3.8/http/client.py", line 307, in begin
    version, status, reason = self._read_status()
  File "/appl/python/3.8.9/lib/python3.8/http/client.py", line 268, in _read_status
    line = str(self.fp.readline(_MAXLINE + 1), "iso-8859-1")
  File "/appl/python/3.8.9/lib/python3.8/socket.py", line 669, in readinto
    return self._sock.recv_into(b)
  File "/appl/python/3.8.9/lib/python3.8/ssl.py", line 1241, in recv_into
    return self.read(nbytes, buffer)
  File "/appl/python/3.8.9/lib/python3.8/ssl.py", line 1099, in read
    return self._sslobj.read(len, buffer)
socket.timeout: The read operation timed out

During handling of the above exception, another exception occurred:

Traceback (most recent call last):
  File "/work3/soeba/HALOS/halos/lib/python3.8/site-packages/requests/adapters.py", line 489, in send
    resp = conn.urlopen(
  File "/work3/soeba/HALOS/halos/lib/python3.8/site-packages/urllib3/connectionpool.py", line 787, in urlopen
    retries = retries.increment(
  File "/work3/soeba/HALOS/halos/lib/python3.8/site-packages/urllib3/util/retry.py", line 550, in increment
    raise six.reraise(type(error), error, _stacktrace)
  File "/work3/soeba/HALOS/halos/lib/python3.8/site-packages/urllib3/packages/six.py", line 770, in reraise
    raise value
  File "/work3/soeba/HALOS/halos/lib/python3.8/site-packages/urllib3/connectionpool.py", line 703, in urlopen
    httplib_response = self._make_request(
  File "/work3/soeba/HALOS/halos/lib/python3.8/site-packages/urllib3/connectionpool.py", line 451, in _make_request
    self._raise_timeout(err=e, url=url, timeout_value=read_timeout)
  File "/work3/soeba/HALOS/halos/lib/python3.8/site-packages/urllib3/connectionpool.py", line 340, in _raise_timeout
    raise ReadTimeoutError(
urllib3.exceptions.ReadTimeoutError: HTTPSConnectionPool(host='api.wandb.ai', port=443): Read timed out. (read timeout=10)

During handling of the above exception, another exception occurred:

Traceback (most recent call last):
  File "/work3/soeba/HALOS/halos/lib/python3.8/site-packages/wandb/sdk/lib/retry.py", line 113, in __call__
    result = self._call_fn(*args, **kwargs)
  File "/work3/soeba/HALOS/halos/lib/python3.8/site-packages/wandb/sdk/internal/internal_api.py", line 204, in execute
    return self.client.execute(*args, **kwargs)  # type: ignore
  File "/work3/soeba/HALOS/halos/lib/python3.8/site-packages/wandb/vendor/gql-0.2.0/wandb_gql/client.py", line 52, in execute
    result = self._get_result(document, *args, **kwargs)
  File "/work3/soeba/HALOS/halos/lib/python3.8/site-packages/wandb/vendor/gql-0.2.0/wandb_gql/client.py", line 60, in _get_result
    return self.transport.execute(document, *args, **kwargs)
  File "/work3/soeba/HALOS/halos/lib/python3.8/site-packages/wandb/vendor/gql-0.2.0/wandb_gql/transport/requests.py", line 38, in execute
    request = requests.post(self.url, **post_args)
  File "/work3/soeba/HALOS/halos/lib/python3.8/site-packages/requests/api.py", line 115, in post
    return request("post", url, data=data, json=json, **kwargs)
  File "/work3/soeba/HALOS/halos/lib/python3.8/site-packages/requests/api.py", line 59, in request
    return session.request(method=method, url=url, **kwargs)
  File "/work3/soeba/HALOS/halos/lib/python3.8/site-packages/requests/sessions.py", line 587, in request
    resp = self.send(prep, **send_kwargs)
  File "/work3/soeba/HALOS/halos/lib/python3.8/site-packages/requests/sessions.py", line 701, in send
    r = adapter.send(request, **kwargs)
  File "/work3/soeba/HALOS/halos/lib/python3.8/site-packages/requests/adapters.py", line 578, in send
    raise ReadTimeout(e, request=request)
requests.exceptions.ReadTimeout: HTTPSConnectionPool(host='api.wandb.ai', port=443): Read timed out. (read timeout=10)
2023-12-19 10:08:03,221 INFO    MainThread:14335 [interface_shared.py:_communicate_run():331] couldn't get run from backend
2023-12-19 10:08:03,222 ERROR   MainThread:14335 [wandb_init.py:init():676] backend process timed out
2023-12-19 10:08:03,222 ERROR   MainThread:14335 [wandb_init.py:init():685] encountered error: Error communicating with wandb process
For more info see: https://docs.wandb.ai/library/init#init-start-error
2023-12-19 10:09:44,008 ERROR   Thread-1  :14335 [internal_api.py:execute():207] 500 response executing GraphQL.
2023-12-19 10:09:44,010 ERROR   Thread-1  :14335 [internal_api.py:execute():208] {"error":"Error 1040 (08004): Too many connections"}
2023-12-19 10:12:07,573 WARNING MsgRouterThr:14335 [router.py:message_loop():76] message_loop has been closed
